<?xml version="1.0" ?>
<!-- This URDF was automatically created by SolidWorks to URDF Exporter! Originally created by Stephen Brawner (brawner@gmail.com) 
     Commit Version: 1.6.0-4-g7f85cfe  Build Version: 1.6.7995.38578
     For more information, please see http://wiki.ros.org/sw_urdf_exporter -->
<robot name="bcar_description">
  <!--skid_steer_drive_controller-->
  <gazebo>
    <plugin filename="libgazebo_ros_diff_drive.so" name="skid_steer_drive_controller">
      <ros>
        <namespace>/gazebo_mobot</namespace>
        <argument>/cmd_vel:=mr_cme_vel</argument>
        <argument>/odom:=odom</argument>
      </ros>
      <update_rate>100.0</update_rate>
      <num_wheel_pairs>2</num_wheel_pairs>
      <odometry_frame>odom</odometry_frame>  <!--里程计数据的参考坐标系，ROS中一般命名为odom -->
      <left_joint>Wheel_FL_joint</left_joint>
      <left_joint>Wheel_RL_joint</left_joint>
      <wheel_separation>0.4</wheel_separation><!-- 两个轮子得间距 -->
      <wheel_diameter>0.2</wheel_diameter>
      <right_joint>Wheel_FR_jiont</right_joint>
      <right_joint>Wheel_RR_joint</right_joint>
      <wheel_separation>0.4</wheel_separation>
      <wheel_diameter>0.2</wheel_diameter>
      <robot_base_frame>robot_footprint</robot_base_frame><!-- 设置controler所控制的机器人的坐标系是哪个坐标系 -->
      <max_wheel_torque>20</max_wheel_torque>
      <publish_odom>true</publish_odom>
      <publish_odom_tf>true</publish_odom_tf>
      <publish_wheel_tf>true</publish_wheel_tf>
      <odometry_source>world</odometry_source>
    </plugin>
  </gazebo>
  <gazebo reference="camera">
    <sensor name="camera_sensor" type="camera">
      <update_rate>30.0</update_rate>
      <always_on>1</always_on>
      <camera name="camera">
        <horizontal_fov>1.3962634</horizontal_fov>
        <image>
          <width>800</width>
          <height>800</height>
          <format>R8G8B8</format>
        </image>
        <clip>
          <near>0.02</near>
          <far>300</far>
        </clip>
        <distortion>
          <k1>0.0</k1>
          <k2>0.0</k2>
          <k3>0.0</k3>
          <p1>0.0</p1>
          <p2>0.0</p2>
          <center>0.5 0.5</center>
        </distortion>
      </camera>
      <plugin filename="libgazebo_ros_camera.so" name="camera_controller">
        <ros>
          <namespace>/gazebo_mobot</namespace>
          <argument>camera/image_raw:=/gazebo_mobot/camera/image</argument>
          <argument>camera/camera_info:=/gazebo_mobot/camera/image/camera_info</argument>
        </ros>
        <camera_name>camera</camera_name>
        <frame_name>camera</frame_name>
        <hack_baseline>0.07</hack_baseline>
      </plugin>
    </sensor>
  </gazebo>
  <gazebo reference="hokuyo">
    <sensor name="head_hokuyo_sensor" type="ray">
      <pose>0 0 0 0 0 0</pose>
      <visualize>false</visualize>
      <update_rate>30</update_rate>
      <ray>
        <scan>
          <horizontal>
            <samples>720</samples>
            <resolution>1</resolution>
            <min_angle>-1.570796</min_angle>
            <max_angle>1.570796</max_angle>
          </horizontal>
        </scan>
        <range>
          <min>0.10</min>
          <max>30.0</max>
          <resolution>0.01</resolution>
        </range>
        <noise>
          <type>gaussian</type>
          <!-- Noise parameters based on published spec for Hokuyo laser
                achieving "+-30mm" accuracy at range < 10m.  A mean of 0.0m and
                stddev of 0.01m will put 99.7% of samples within 0.03m of the true
                reading. -->
          <mean>0.0</mean>
          <stddev>0.01</stddev>
        </noise>
      </ray>
      <update_rate>30</update_rate>
      <plugin filename="libgazebo_ros_ray_sensor.so" name="gazebo_ros_head_hokuyo_controller">
        <ros>
          <namespace>/gazebo_mobot</namespace>
          <argument>~/out:=scan</argument>
        </ros>
        <output_type>sensor_msgs/LaserScan</output_type>
      </plugin>
    </sensor>
  </gazebo>
  <link name="robot_footprint"/>
  <joint name="robot_footprint_joint" type="fixed">
    <origin rpy="0 0 0" xyz="0 0 0"/>
    <parent link="robot_footprint"/>
    <child link="base_link"/>
  </joint>
  <link name="base_link">
    <pose>0 0 0.1 0 0 0</pose>
    <inertial>
      <origin xyz="0 0 0" rpy="0.0 0 0"/>
      <mass value="30.0"/>
      <inertia ixx="0" ixy="0" ixz="0" iyy="0" iyz="0" izz="0"/>
    </inertial>
    <visual name="basic_visual">
      <origin xyz="-0.144 -0.073 0" rpy="0 0 0"/>
      <geometry>
        <!-- <box size=".4 .2 .1"/> -->
        <mesh filename="/home/change/ros2_ws/src/gazebo_mobot/meshes/base_link.STL"/>
      </geometry>
    </visual>
    <collision name="collision">
      <origin xyz="-0.144 -0.073 0" rpy="0 0 0"/>
      <geometry>
        <!-- <box size=".4 .2 .1"/> -->
        <mesh filename="/home/change/ros2_ws/src/gazebo_mobot/meshes/base_link.STL" />
      </geometry>
    </collision>
  </link>
  <link name="Wheel_FL">
    <inertial>
      <origin xyz="0.0 0 0" rpy="0 0 0"/>
      <mass value="5.0"/>
      <inertia ixx="0" ixy="0" ixz="0" iyy="0" iyz="0" izz="0"/>
    </inertial>
    <visual>
      <origin xyz="0 0 0" rpy="0 0 0"/>
      <geometry>
        <!-- <cylinder length="0.05" radius="0.06"/> -->
        <mesh filename="/home/change/ros2_ws/src/gazebo_mobot/meshes/Wheel_FL.STL"/>
      </geometry>
    </visual>
    <collision>
      <origin xyz="0 0 0" rpy="0 0 0"/>
      <geometry>
        <!-- <cylinder length="0.05" radius="0.06"/> -->
        <mesh filename="/home/change/ros2_ws/src/gazebo_mobot/meshes/Wheel_FL.STL"/>
      </geometry>
    </collision>
  </link>
  <link name="Wheel_FR">
    <inertial>
      <origin xyz="0 0 0" rpy="0 0 0"/>
      <mass value="5.0"/>
      <inertia ixx="0" ixy="0" ixz="0" iyy="0" iyz="0" izz="0"/>
    </inertial>
    <visual>
      <origin xyz="0 0 0" rpy="0 0 0"/>
      <geometry>
        <!-- <cylinder length="0.05" radius="0.06"/> -->
        <mesh filename="/home/change/ros2_ws/src/gazebo_mobot/meshes/Wheel_FR.STL"/>
      </geometry>
    </visual>
    <collision>
      <origin xyz="0 0 0" rpy="0 0 0"/>
      <geometry>
        <!-- <cylinder length="0.05" radius="0.06"/> -->
        <mesh filename="/home/change/ros2_ws/src/gazebo_mobot/meshes/Wheel_FR.STL" />
      </geometry>
    </collision>
  </link>
  <link name="Wheel_RL">
    <inertial>
      <origin xyz="0 0 0" rpy="0 0 0"/>
      <mass value="5.0"/>
      <inertia ixx="0" ixy="0" ixz="0" iyy="0" iyz="0" izz="0"/>
    </inertial>
    <visual>
      <origin xyz="0 0 0" rpy="0 0 0"/>
      <geometry>
        <!-- <cylinder length="0.05" radius="0.06"/> -->
        <mesh filename="/home/change/ros2_ws/src/gazebo_mobot/meshes/Wheel_RL.STL" />
      </geometry>
    </visual>
    <collision>
      <origin xyz="0 0 0" rpy="0 0 0" />
      <geometry>
        <!-- <cylinder length="0.05" radius="0.06"/> -->
        <mesh filename="/home/change/ros2_ws/src/gazebo_mobot/meshes/Wheel_RL.STL" />
      </geometry>
    </collision>
  </link>
  <link name="Wheel_RR">
    <inertial>
      <origin xyz="0 0 0" rpy="0 0 0"/>
      <mass value="5.0"/>
      <inertia ixx="0" ixy="0" ixz="0" iyy="0" iyz="0" izz="0"/>
    </inertial>
    <visual>
      <origin xyz="0 0 0" rpy="0 0 0"/>
      <geometry>
        <!-- <cylinder length="0.05" radius="0.06"/> -->
        <mesh filename="/home/change/ros2_ws/src/gazebo_mobot/meshes/Wheel_RR.STL" />
      </geometry>
    </visual>
    <collision>
      <origin xyz="0 0 0" rpy="0 0 0"/>
      <geometry>
        <!-- <cylinder length="0.05" radius="0.06"/> -->
        <mesh filename="/home/change/ros2_ws/src/gazebo_mobot/meshes/Wheel_RR.STL"/>
      </geometry>
    </collision>
  </link>
  <link name="camera">
    <inertial>
      <mass value="0.001"/>
      <origin rpy=" 0 0 0" xyz="0.05 0.05 0.05"/>
      <inertia ixx="0" ixy="0" ixz="0" iyy="0" iyz="0" izz="0"/>
    </inertial>
    <visual name="camera_visual">
      <origin rpy="0 0 0" xyz="0 0 0"/>
      <geometry>
        <box size="0.05 0.05 0.05"/>
      </geometry>
    </visual>
    <collision name="camera_colision">
      <origin rpy="0 0 0" xyz="0 0 0"/>
      <geometry>
        <box size="0.05 0.05 0.05"/>
      </geometry>
    </collision>
  </link>
  <link name="hokuyo">
    <inertial>
      <mass value="1e-5"/>
      <origin rpy=" 0 0 0" xyz="0 0 0"/>
      <inertia ixx="1e-6" ixy="0" ixz="0" iyy="1e-6" iyz="0" izz="1e-6"/>
    </inertial>
    <visual name="hokuyo_visual">
      <origin rpy="0 0 0" xyz="0 0 0"/>
      <geometry>
        <!-- <mesh filename="$(find mobot)/meshes/hokuyo.dae"/> -->
        <box size="0.05 0.05 0.05"/>
      </geometry>
    </visual>
    <collision name="hokuyo_colision">
      <origin rpy="0 0 0" xyz="0 0 0"/>
      <geometry>
        <box size="0.1 0.1 0.1"/>
      </geometry>
    </collision>
  </link>
  <joint name="Wheel_FL_joint" type="continuous">
    <origin xyz="0.14463 0.07419 0" rpy="0 0 0"/>
    <parent link="base_link"/>
    <child link="Wheel_FL"/>
    <axis xyz="0 1 0" rpy="0 0 0"/>
    <limit effort="10000" velocity="1000"/>
    <dynamics damping="1.0" friction="1.0"/>
  </joint>
  <joint name="Wheel_FR_jiont" type="continuous">
    <origin xyz="0.14463 -0.07419 0" rpy="0 0 0"/>
    <parent link="base_link"/>
    <child link="Wheel_FR"/>
    <axis xyz="0 1 0" rpy="0 0 0"/>
    <limit effort="10000" velocity="1000"/>
    <dynamics damping="1.0" friction="1.0"/>
  </joint>
  <joint name="Wheel_RL_joint" type="continuous">
    <origin xyz="-0.14463 0.07419 0" rpy="0 0 0"/>
    <parent link="base_link"/>
    <child link="Wheel_RL"/>
    <axis xyz="0 1 0" rpy="0 0 0"/>
    <limit effort="10000" velocity="1000"/>
    <dynamics damping="1.0" friction="1.0"/>
  </joint>
  <joint name="Wheel_RR_joint" type="continuous">
    <origin xyz="-0.14463 -0.07419 0" rpy="0 0 0"/>
    <parent link="base_link"/>
    <child link="Wheel_RR"/>
    <axis xyz="0 1 0" rpy="0 0 0"/>
    <limit effort="10000" velocity="1000"/>
    <dynamics damping="1.0" friction="1.0"/>
  </joint>
  <joint name="camera_joint" type="fixed">
    <origin rpy="0 0 0" xyz="0.2 0 0.05"/>
    <child link="camera"/>
    <parent link="base_link"/>
    <axis rpy="0 0 0" xyz="0 1 0"/>
  </joint>
  <joint name="hokuyo_joint" type="continuous">
    <origin rpy="0 0 0" xyz="0.15 0 0.1"/>
    <child link="hokuyo"/>
    <parent link="base_link"/>
    <axis rpy="0 0 0" xyz="0 1 0"/>
  </joint>
  <gazebo reference="base_link">
    <material>Gazebo/Red</material>
  </gazebo>
  <gazebo reference="Wheel_FL">
    <material>Gazebo/Gray</material>
  </gazebo>
  <gazebo reference="Wheel_FR">
    <material>Gazebo/Gray</material>
  </gazebo>
  <gazebo reference="Wheel_RL">
    <material>Gazebo/Gray</material>
  </gazebo>
  <gazebo reference="Wheel_RR">
    <material>Gazebo/Gray</material>
  </gazebo>
  <gazebo reference="camera">
    <material>Gazebo/Red</material>
  </gazebo>
  <gazebo reference="hokuyo">
    <material>Gazebo/Black</material>
  </gazebo>
</robot>